<?xml version="1.0" ?>
<robot name="simple_arm_with_torso">
<material name="color">
    <color rgba="0.1 0.1 0.1 1"/>
</material>

<!-- Torso Link -->
  <link name="torso">
    <visual>
      <origin xyz="0  0 0.5" rpy="0 0 0" />
      <geometry>
        <box size="0.5 1 1"/>
      </geometry>
      <material name="blue">
        <color rgba="0 0 1 1"/>
      </material>
    </visual>
    <collision>
      <origin xyz="0  0 0.5" rpy="0 0 0" />
      <geometry>
        <box size="0.5 0.5 0.5"/>
      </geometry>
    </collision>
    <inertial>
      <origin xyz="0  0 0.5" rpy="0 0 0" />
      <mass value="1.0"/>
      <inertia ixx="0.083" ixy="0.0" ixz="0.0" iyy="0.083" iyz="0.0" izz="0.083"/>
    </inertial>
  </link>

  <!-- Upper Arm Link -->
  <link name="upper_arm">
    <visual>
      <origin xyz="0  0  0.50" rpy="0 0 0" />
      <geometry>
        <cylinder length="1" radius="0.1"/>
      </geometry>
    </visual>
    <collision>
      <origin xyz="0  0  0.50" rpy="0 0 0" />
      <geometry>
        <cylinder length="1" radius="0.1"/>
      </geometry>
    </collision>
    <inertial>
      <origin xyz="0  0  0.50" rpy="0 0 0" />
      <mass value="1.0"/>
      <inertia ixx="0.083" ixy="0.083" ixz="0.083" iyy="0.083" iyz="0.083" izz="0.083"/>
    </inertial>
  </link>
  <link name="upper_arm1">
    <inertial>
      <mass value="0"/>
      <origin xyz="0 0 0" rpy="0 0 0" />
      <inertia ixx="0" iyy="0" izz="0" ixy="0" ixz="0" iyz="0"/>
    </inertial>
  </link>

  <!-- Forearm Link -->
   <link name="forarm">
    <visual>
      <origin xyz="0  0  0.50" rpy="0 0 0" />
      <geometry>
        <cylinder length="1" radius="0.1"/>
      </geometry>
    </visual>
    <collision>
      <origin xyz="0  0  0.50" rpy="0 0 0" />
      <geometry>
        <cylinder length="1" radius="0.1"/>
      </geometry>
    </collision>
    <inertial>
      <origin xyz="0  0  0.50" rpy="0 0 0" />
      <mass value="1.0"/>
      <inertia ixx="0.083" ixy="0.083" ixz="0.083" iyy="0.083" iyz="0.083" izz="0.083"/>
    </inertial>
  </link>
  <link name="forarm1">
    <inertial>
      <mass value="0"/>
      <origin xyz="0 0 0" rpy="0 0 0" />
      <inertia ixx="0" iyy="0" izz="0" ixy="0" ixz="0" iyz="0"/>
    </inertial>
  </link>

  <!-- sphere Link -->
  <!-- <link name="sphere">
    <origin xyz="0 0 0" rpy="0 0 0"/>
    <visual>
      <geometry>
        <sphere radius="0.1"/>
      </geometry>
    </visual>
    <inertial>
      <origin xyz="0 0 0" rpy="0 0 0"/>
      <mass value="0.1"/>
      <inertia ixx="0.000025" ixy="0" ixz="0" iyy="0.000025" iyz="0" izz="0.000025"/>
    </inertial>
  </link> -->
  <!--word link --> 
  <link name="world">
  </link>
  <!-- Joints -->
  <!-- World to Torso (Fixed Joint) -->
    <joint name="world_to_torso" type="fixed">
      <parent link="world"/>
      <child link="torso"/>
      <origin xyz="0 0 0"/>
    </joint>
  <!-- Torso to Upper Arm -->
    <joint name="torso_to_upper_arm1" type="revolute">
      <origin xyz="0 0.5 1" rpy="0 0 0"/>
      <parent link="torso"/>
      <child link="upper_arm1"/>
      <dynamics damping="0.1" friction="0.0"/>
      <limit effort="30" velocity="1.0" lower="-15" upper="15" />
      <axis xyz="0 1 0" />
    </joint>
    <joint name="_upper_arm1_to_upper_arm" type="revolute">
      <origin xyz="0 0 0" rpy="0 0 0"/>
      <parent link="upper_arm1"/>
      <child link="upper_arm"/>
      <dynamics damping="0.1" friction="0.0"/>
      <limit effort="30" velocity="1.0" lower="-15.0" upper="15.0" />
      <axis xyz="1 0 0" />
    </joint>
        <joint name="upperarm_to_forarm1" type="revolute">
      <origin xyz="0 0 1" rpy="0 0 0"/>
      <parent link="upper_arm"/>
      <child link="forarm1"/>
      <dynamics damping="0.1" friction="0.0"/>
      <limit effort="30" velocity="1.0" lower="-15" upper="15" />
      <axis xyz="1 0 0" />
    </joint>
    <joint name="forarm1_to_forarm" type="revolute">
      <origin xyz="0 0 0" rpy="0 0 0"/>
      <parent link="forarm1"/>
      <child link="forarm"/>
      <dynamics damping="0.1" friction="0.0"/>
      <limit effort="30" velocity="1.0" lower="-15.0" upper="15.0" />
      <axis xyz="0 1 0" />
    </joint>
   
  <!--Forearm to hand-->
    <!-- <joint name="forearm_to_sphere" type="fixed">
      <origin xyz="0 0 1"/>
      <parent link="forearm"/>
      <child link="sphere"/>
    </joint> -->

</robot>
